<robot
  name="armrobot">
  <link
    name="base_link">
    <inertial>
      <origin
        xyz="0.0176061748588041 -0.324486216929227 0.110499479656354"
        rpy="0 0 0" />
      <mass
        value="1.46079346002943" />
      <inertia
        ixx="0.0149175345769698"
        ixy="6.20385459415203E-22"
        ixz="4.16763853451283E-18"
        iyy="0.0149175345769698"
        iyz="1.81572253156349E-18"
        izz="0.0217682754648218" />
    </inertial>
    <visual>
      <origin
        xyz="0 0 0"
        rpy="0 0 0" />
      <geometry>
        <mesh
          filename="package://armrobot/meshes/base_link.STL" />
      </geometry>
      <material
        name="">
        <color
          rgba="0.792156862745098 0.819607843137255 0.933333333333333 1" />
      </material>
    </visual>
    <collision>
      <origin
        xyz="0 0 0"
        rpy="0 0 0" />
      <geometry>
        <mesh
          filename="package://armrobot/meshes/base_link.STL" />
      </geometry>
    </collision>
  </link>
  <link
    name="link01">
    <inertial>
      <origin
        xyz="0.00129360549058061 0.024235592989766 1.11022302462516E-16"
        rpy="0 0 0" />
      <mass
        value="0.347308358901827" />
      <inertia
        ixx="0.00138773508977893"
        ixy="1.02146472184429E-05"
        ixz="3.79470760369927E-18"
        iyy="0.00308679444190769"
        iyz="-5.68359107607636E-19"
        izz="0.0022788533434689" />
    </inertial>
    <visual>
      <origin
        xyz="0 0 0"
        rpy="0 0 0" />
      <geometry>
        <mesh
          filename="package://armrobot/meshes/link01.STL" />
      </geometry>
      <material
        name="">
        <color
          rgba="0.792156862745098 0.819607843137255 0.933333333333333 1" />
      </material>
    </visual>
    <collision>
      <origin
        xyz="0 0 0"
        rpy="0 0 0" />
      <geometry>
        <mesh
          filename="package://armrobot/meshes/link01.STL" />
      </geometry>
    </collision>
  </link>
  <joint
    name="joint1"
    type="continuous">
    <origin
      xyz="0.017606 -0.32449 0.2368"
      rpy="1.5708 -2.9332E-17 -0.49956" />
    <parent
      link="base_link" />
    <child
      link="link01" />
    <axis
      xyz="0 1 0" />
    <limit
      effort="2"
      velocity="1" />
  </joint>
  <link
    name="link12">
    <inertial>
      <origin
        xyz="-0.0981193147488483 -1.60982338570648E-15 0.00200000000000172"
        rpy="0 0 0" />
      <mass
        value="1.11937048019661" />
      <inertia
        ixx="0.00801988163772991"
        ixy="4.09286320113278E-18"
        ixz="-5.01443504774546E-19"
        iyy="0.00856877454331104"
        iyz="1.73472347597681E-18"
        izz="0.00767533470843555" />
    </inertial>
    <visual>
      <origin
        xyz="0 0 0"
        rpy="0 0 0" />
      <geometry>
        <mesh
          filename="package://armrobot/meshes/link12.STL" />
      </geometry>
      <material
        name="">
        <color
          rgba="0.792156862745098 0.819607843137255 0.933333333333333 1" />
      </material>
    </visual>
    <collision>
      <origin
        xyz="0 0 0"
        rpy="0 0 0" />
      <geometry>
        <mesh
          filename="package://armrobot/meshes/link12.STL" />
      </geometry>
    </collision>
  </link>
  <joint
    name="joint2"
    type="revolute">
    <origin
      xyz="0 0.081 0"
      rpy="1.5708 -0.073077 -1.5708" />
    <parent
      link="link01" />
    <child
      link="link12" />
    <axis
      xyz="0 0 -1" />
    <limit
      lower="-1.7453"
      upper="1.7453"
      effort="2"
      velocity="1" />
  </joint>
  <link
    name="link23">
    <inertial>
      <origin
        xyz="0.151955789611616 -2.9270080563748E-06 0.00185292700805606"
        rpy="0 0 0" />
      <mass
        value="5.49535706052116" />
      <inertia
        ixx="0.0312656752330393"
        ixy="-1.17349054812397E-06"
        ixz="1.17349054813091E-06"
        iyy="0.0323597342624823"
        iyz="-6.43445256244459E-07"
        izz="0.0307674107157527" />
    </inertial>
    <visual>
      <origin
        xyz="0 0 0"
        rpy="0 0 0" />
      <geometry>
        <mesh
          filename="package://armrobot/meshes/link23.STL" />
      </geometry>
      <material
        name="">
        <color
          rgba="0.792156862745098 0.819607843137255 0.933333333333333 1" />
      </material>
    </visual>
    <collision>
      <origin
        xyz="0 0 0"
        rpy="0 0 0" />
      <geometry>
        <mesh
          filename="package://armrobot/meshes/link23.STL" />
      </geometry>
    </collision>
  </link>
  <joint
    name="joint3"
    type="revolute">
    <origin
      xyz="-0.197 0 0"
      rpy="3.3862E-15 -5.218E-15 -2.2721" />
    <parent
      link="link12" />
    <child
      link="link23" />
    <axis
      xyz="0 0 -1" />
    <limit
      lower="-1.7453"
      upper="1.7453"
      effort="2"
      velocity="1" />
  </joint>
  <link
    name="link34">
    <inertial>
      <origin
        xyz="-0.0169642442294969 -2.22044604925031E-16 1.38777878078145E-16"
        rpy="0 0 0" />
      <mass
        value="2.79074113501019" />
      <inertia
        ixx="0.0161908942780376"
        ixy="-3.46944695195361E-18"
        ixz="-1.0842021724855E-18"
        iyy="0.0114011057306674"
        iyz="-4.11996825544492E-18"
        izz="0.0101991187528917" />
    </inertial>
    <visual>
      <origin
        xyz="0 0 0"
        rpy="0 0 0" />
      <geometry>
        <mesh
          filename="package://armrobot/meshes/link34.STL" />
      </geometry>
      <material
        name="">
        <color
          rgba="0.792156862745098 0.819607843137255 0.933333333333333 1" />
      </material>
    </visual>
    <collision>
      <origin
        xyz="0 0 0"
        rpy="0 0 0" />
      <geometry>
        <mesh
          filename="package://armrobot/meshes/link34.STL" />
      </geometry>
    </collision>
  </link>
  <joint
    name="joint4"
    type="continuous">
    <origin
      xyz="0.30331 0 0.00185"
      rpy="-3.1304 1.1657E-15 3.1086E-15" />
    <parent
      link="link23" />
    <child
      link="link34" />
    <axis
      xyz="1 0 0" />
    <limit
      effort="2"
      velocity="1" />
  </joint>
  <link
    name="link45">
    <inertial>
      <origin
        xyz="0.0999176864544128 -6.66133814775094E-16 6.10622663543836E-16"
        rpy="0 0 0" />
      <mass
        value="1.65897773866094" />
      <inertia
        ixx="0.00960236744018954"
        ixy="3.49655200626575E-18"
        ixz="4.33680868994202E-19"
        iyy="0.0129478744379157"
        iyz="6.05797963876276E-18"
        izz="0.00949418899234963" />
    </inertial>
    <visual>
      <origin
        xyz="0 0 0"
        rpy="0 0 0" />
      <geometry>
        <mesh
          filename="package://armrobot/meshes/link45.STL" />
      </geometry>
      <material
        name="">
        <color
          rgba="0.792156862745098 0.819607843137255 0.933333333333333 1" />
      </material>
    </visual>
    <collision>
      <origin
        xyz="0 0 0"
        rpy="0 0 0" />
      <geometry>
        <mesh
          filename="package://armrobot/meshes/link45.STL" />
      </geometry>
    </collision>
  </link>
  <joint
    name="joint5"
    type="revolute">
    <origin
      xyz="0.081686 0 0"
      rpy="-9.4716E-16 -1.1102E-16 -0.61164" />
    <parent
      link="link34" />
    <child
      link="link45" />
    <axis
      xyz="0 0 1" />
    <limit
      lower="-0.017453"
      upper="0.017453"
      effort="2"
      velocity="1" />
  </joint>
  <link
    name="link56">
    <inertial>
      <origin
        xyz="0.0499809574738659 5.55111512312578E-16 6.66133814775094E-16"
        rpy="0 0 0" />
      <mass
        value="0.444019858497779" />
      <inertia
        ixx="0.000996979236728048"
        ixy="4.65868120989865E-19"
        ixz="-2.16840434497101E-19"
        iyy="0.00135582146654638"
        iyz="5.30242624981192E-19"
        izz="0.00135582146654638" />
    </inertial>
    <visual>
      <origin
        xyz="0 0 0"
        rpy="0 0 0" />
      <geometry>
        <mesh
          filename="package://armrobot/meshes/link56.STL" />
      </geometry>
      <material
        name="">
        <color
          rgba="0.792156862745098 0.819607843137255 0.933333333333333 1" />
      </material>
    </visual>
    <collision>
      <origin
        xyz="0 0 0"
        rpy="0 0 0" />
      <geometry>
        <mesh
          filename="package://armrobot/meshes/link56.STL" />
      </geometry>
    </collision>
  </link>
  <joint
    name="joint6"
    type="prismatic">
    <origin
      xyz="0.20297 0 0"
      rpy="0 3.8858E-16 3.1416" />
    <parent
      link="link45" />
    <child
      link="link56" />
    <axis
      xyz="1 0 0" />
    <limit
      lower="0"
      upper="10"
      effort="2"
      velocity="1" />
  </joint>
</robot>
