<robot
  name="armrobo">
  <link
    name="base_link">
    <inertial>
      <origin
        xyz="-0.00025759 0.043891 -0.00016095"
        rpy="0 0 0" />
      <mass
        value="1.4608" />
      <inertia
        ixx="0.014918"
        ixy="3.9604E-18"
        ixz="-2.068E-22"
        iyy="0.021768"
        iyz="-5.3565E-19"
        izz="0.014918" />
    </inertial>
    <visual>
      <origin
        xyz="0 0 0"
        rpy="0 0 0" />
      <geometry>
        <mesh
          filename="package://armrobo/meshes/base_link.STL" />
      </geometry>
      <material
        name="">
        <color
          rgba="0.79216 0.81961 0.93333 1" />
      </material>
    </visual>
    <collision>
      <origin
        xyz="0 0 0"
        rpy="0 0 0" />
      <geometry>
        <mesh
          filename="package://armrobo/meshes/base_link.STL" />
      </geometry>
    </collision>
  </link>
  <link
    name="link01">
    <inertial>
      <origin
        xyz="0.0012936 0.024236 2.1196E-17"
        rpy="0 0 0" />
      <mass
        value="0.34731" />
      <inertia
        ixx="0.0013877"
        ixy="1.0215E-05"
        ixz="8.1315E-19"
        iyy="0.0030868"
        iyz="-1.1774E-19"
        izz="0.0022789" />
    </inertial>
    <visual>
      <origin
        xyz="0 0 0"
        rpy="0 0 0" />
      <geometry>
        <mesh
          filename="package://armrobo/meshes/link01.STL" />
      </geometry>
      <material
        name="">
        <color
          rgba="0.79216 0.81961 0.93333 1" />
      </material>
    </visual>
    <collision>
      <origin
        xyz="0 0 0"
        rpy="0 0 0" />
      <geometry>
        <mesh
          filename="package://armrobo/meshes/link01.STL" />
      </geometry>
    </collision>
  </link>
  <joint
    name="joint1"
    type="continuous">
    <origin
      xyz="-0.00025759 0.00016095 0.17019"
      rpy="1.5708 -2.9332E-17 -0.49956" />
    <parent
      link="base_link" />
    <child
      link="link01" />
    <axis
      xyz="0 1 0" />
    <limit
      effort="2"
      velocity="10" />
  </joint>
  <link
    name="link12">
    <inertial>
      <origin
        xyz="-0.098119 -3.7678E-15 0.002"
        rpy="0 0 0" />
      <mass
        value="1.1194" />
      <inertia
        ixx="0.0080199"
        ixy="3.9844E-18"
        ixz="1.2875E-18"
        iyy="0.0085688"
        iyz="-1.0842E-18"
        izz="0.0076753" />
    </inertial>
    <visual>
      <origin
        xyz="0 0 0"
        rpy="0 0 0" />
      <geometry>
        <mesh
          filename="package://armrobo/meshes/link12.STL" />
      </geometry>
      <material
        name="">
        <color
          rgba="0.79216 0.81961 0.93333 1" />
      </material>
    </visual>
    <collision>
      <origin
        xyz="0 0 0"
        rpy="0 0 0" />
      <geometry>
        <mesh
          filename="package://armrobo/meshes/link12.STL" />
      </geometry>
    </collision>
  </link>
  <joint
    name="joint2"
    type="revolute">
    <origin
      xyz="0 0.081 0"
      rpy="1.5708 -0.073077 -1.5708" />
    <parent
      link="link01" />
    <child
      link="link12" />
    <axis
      xyz="0 0 -1" />
    <limit
      lower="-1.7453"
      upper="1.7453"
      effort="2"
      velocity="10" />
  </joint>
  <link
    name="link23">
    <inertial>
      <origin
        xyz="0.15196 -2.927E-06 0.0018529"
        rpy="0 0 0" />
      <mass
        value="5.4954" />
      <inertia
        ixx="0.031266"
        ixy="-1.1735E-06"
        ixz="1.1735E-06"
        iyy="0.03236"
        iyz="-6.4345E-07"
        izz="0.030767" />
    </inertial>
    <visual>
      <origin
        xyz="0 0 0"
        rpy="0 0 0" />
      <geometry>
        <mesh
          filename="package://armrobo/meshes/link23.STL" />
      </geometry>
      <material
        name="">
        <color
          rgba="0.79216 0.81961 0.93333 1" />
      </material>
    </visual>
    <collision>
      <origin
        xyz="0 0 0"
        rpy="0 0 0" />
      <geometry>
        <mesh
          filename="package://armrobo/meshes/link23.STL" />
      </geometry>
    </collision>
  </link>
  <joint
    name="joint3"
    type="revolute">
    <origin
      xyz="-0.197 0 0"
      rpy="2.8588E-15 -2.5535E-15 -2.2721" />
    <parent
      link="link12" />
    <child
      link="link23" />
    <axis
      xyz="0 0 -1" />
    <limit
      lower="-1.7453"
      upper="1.7453"
      effort="2"
      velocity="10" />
  </joint>
  <link
    name="link34">
    <inertial>
      <origin
        xyz="-0.016964 -5.5511E-17 -6.9389E-17"
        rpy="0 0 0" />
      <mass
        value="2.7907" />
      <inertia
        ixx="0.016191"
        ixy="-1.301E-17"
        ixz="3.0358E-18"
        iyy="0.011401"
        iyz="-7.5894E-18"
        izz="0.010199" />
    </inertial>
    <visual>
      <origin
        xyz="0 0 0"
        rpy="0 0 0" />
      <geometry>
        <mesh
          filename="package://armrobo/meshes/link34.STL" />
      </geometry>
      <material
        name="">
        <color
          rgba="0.79216 0.81961 0.93333 1" />
      </material>
    </visual>
    <collision>
      <origin
        xyz="0 0 0"
        rpy="0 0 0" />
      <geometry>
        <mesh
          filename="package://armrobo/meshes/link34.STL" />
      </geometry>
    </collision>
  </link>
  <joint
    name="joint4"
    type="continuous">
    <origin
      xyz="0.30331 0 0.00185"
      rpy="-3.1304 5.5511E-17 8.8818E-16" />
    <parent
      link="link23" />
    <child
      link="link34" />
    <axis
      xyz="1 0 0" />
    <limit
      effort="2"
      velocity="10" />
  </joint>
  <link
    name="link45">
    <inertial>
      <origin
        xyz="0.099918 1.1102E-16 2.498E-16"
        rpy="0 0 0" />
      <mass
        value="1.659" />
      <inertia
        ixx="0.0096024"
        ixy="2.5208E-18"
        ixz="8.6736E-19"
        iyy="0.012948"
        iyz="6.3155E-18"
        izz="0.0094942" />
    </inertial>
    <visual>
      <origin
        xyz="0 0 0"
        rpy="0 0 0" />
      <geometry>
        <mesh
          filename="package://armrobo/meshes/link45.STL" />
      </geometry>
      <material
        name="">
        <color
          rgba="0.79216 0.81961 0.93333 1" />
      </material>
    </visual>
    <collision>
      <origin
        xyz="0 0 0"
        rpy="0 0 0" />
      <geometry>
        <mesh
          filename="package://armrobo/meshes/link45.STL" />
      </geometry>
    </collision>
  </link>
  <joint
    name="joint5"
    type="revolute">
    <origin
      xyz="0.081686 0 0"
      rpy="-1.1553E-15 -1.3323E-15 -0.61164" />
    <parent
      link="link34" />
    <child
      link="link45" />
    <axis
      xyz="0 0 1" />
    <limit
      lower="-1.7453"
      upper="1.7453"
      effort="2"
      velocity="10" />
  </joint>
  <link
    name="link56">
    <inertial>
      <origin
        xyz="-0.050019 0 -8.3267E-17"
        rpy="0 0 0" />
      <mass
        value="0.44402" />
      <inertia
        ixx="0.00099698"
        ixy="5.3194E-19"
        ixz="-6.5052E-19"
        iyy="0.0013558"
        iyz="6.8525E-19"
        izz="0.0013558" />
    </inertial>
    <visual>
      <origin
        xyz="0 0 0"
        rpy="0 0 0" />
      <geometry>
        <mesh
          filename="package://armrobo/meshes/link56.STL" />
      </geometry>
      <material
        name="">
        <color
          rgba="0.79216 0.81961 0.93333 1" />
      </material>
    </visual>
    <collision>
      <origin
        xyz="0 0 0"
        rpy="0 0 0" />
      <geometry>
        <mesh
          filename="package://armrobo/meshes/link56.STL" />
      </geometry>
    </collision>
  </link>
  <joint
    name="joint6"
    type="prismatic">
    <origin
      xyz="0.1298 0 0"
      rpy="0 5.5511E-17 3.1416" />
    <parent
      link="link45" />
    <child
      link="link56" />
    <axis
      xyz="-1 0 0" />
    <limit
      lower="0"
      upper="0.1"
      effort="2"
      velocity="10" />
  </joint>
</robot>
