<robot
  name="arm_descs">
  <link
    name="base_link">
    <inertial>
      <origin
        xyz="-0.000257590501677458 0.0438910721504651 -0.000160951844383809"
        rpy="0 0 0" />
      <mass
        value="1.46079346002943" />
      <inertia
        ixx="0.0149175345769698"
        ixy="4.35696941941122E-18"
        ixz="-1.03397576568925E-22"
        iyy="0.0217682754648218"
        iyz="-3.97894829853511E-19"
        izz="0.0149175345769698" />
    </inertial>
    <visual>
      <origin
        xyz="0 0 0"
        rpy="0 0 0" />
      <geometry>
        <mesh
          filename="package://arm_descs/meshes/base_link.STL" />
      </geometry>
      <material
        name="">
        <color
          rgba="0.792156862745098 0.819607843137255 0.933333333333333 1" />
      </material>
    </visual>
    <collision>
      <origin
        xyz="0 0 0"
        rpy="0 0 0" />
      <geometry>
        <mesh
          filename="package://arm_descs/meshes/base_link.STL" />
      </geometry>
    </collision>
  </link>
  <link
    name="link01">
    <inertial>
      <origin
        xyz="0.00129360549058086 0.0242355929897659 3.75405002223106E-17"
        rpy="0 0 0" />
      <mass
        value="0.347308358901828" />
      <inertia
        ixx="0.00138773508977893"
        ixy="1.02146472184428E-05"
        ixz="5.96311194867027E-19"
        iyy="0.0030867944419077"
        iyz="5.0821976835258E-20"
        izz="0.0022788533434689" />
    </inertial>
    <visual>
      <origin
        xyz="0 0 0"
        rpy="0 0 0" />
      <geometry>
        <mesh
          filename="package://arm_descs/meshes/link01.STL" />
      </geometry>
      <material
        name="">
        <color
          rgba="0.792156862745098 0.819607843137255 0.933333333333333 1" />
      </material>
    </visual>
    <collision>
      <origin
        xyz="0 0 0"
        rpy="0 0 0" />
      <geometry>
        <mesh
          filename="package://arm_descs/meshes/link01.STL" />
      </geometry>
    </collision>
  </link>
  <joint
    name="joint1"
    type="continuous">
    <origin
      xyz="-0.00025759 0.00016095 0.17019"
      rpy="1.5708 -2.9332E-17 -0.49956" />
    <parent
      link="base_link" />
    <child
      link="link01" />
    <axis
      xyz="0 1 0" />
    <limit
      effort="2"
      velocity="10" />
  </joint>
  <link
    name="link12">
    <inertial>
      <origin
        xyz="-0.0981193147488462 5.908901840046E-17 0.00200000000000011"
        rpy="0 0 0" />
      <mass
        value="1.11937048019661" />
      <inertia
        ixx="0.00801988163772992"
        ixy="1.21888041109894E-18"
        ixz="-2.15231071897318E-18"
        iyy="0.00856877454331103"
        iyz="6.07153216591882E-18"
        izz="0.00767533470843554" />
    </inertial>
    <visual>
      <origin
        xyz="0 0 0"
        rpy="0 0 0" />
      <geometry>
        <mesh
          filename="package://arm_descs/meshes/link12.STL" />
      </geometry>
      <material
        name="">
        <color
          rgba="0.792156862745098 0.819607843137255 0.933333333333333 1" />
      </material>
    </visual>
    <collision>
      <origin
        xyz="0 0 0"
        rpy="0 0 0" />
      <geometry>
        <mesh
          filename="package://arm_descs/meshes/link12.STL" />
      </geometry>
    </collision>
  </link>
  <joint
    name="joint2"
    type="revolute">
    <origin
      xyz="0 0.081 0"
      rpy="1.5708 0.0023901 -1.5708" />
    <parent
      link="link01" />
    <child
      link="link12" />
    <axis
      xyz="0 0 1" />
    <limit
      lower="-1.7453"
      upper="1.7453"
      effort="2"
      velocity="10" />
  </joint>
  <link
    name="link23">
    <inertial>
      <origin
        xyz="0.151955789611622 -2.92700805848835E-06 0.00185292700805596"
        rpy="0 0 0" />
      <mass
        value="5.49535706052116" />
      <inertia
        ixx="0.0312656752330394"
        ixy="-1.17349054813539E-06"
        ixz="1.17349054812828E-06"
        iyy="0.0323597342624823"
        iyz="-6.4344525624576E-07"
        izz="0.0307674107157527" />
    </inertial>
    <visual>
      <origin
        xyz="0 0 0"
        rpy="0 0 0" />
      <geometry>
        <mesh
          filename="package://arm_descs/meshes/link23.STL" />
      </geometry>
      <material
        name="">
        <color
          rgba="0.792156862745098 0.819607843137255 0.933333333333333 1" />
      </material>
    </visual>
    <collision>
      <origin
        xyz="0 0 0"
        rpy="0 0 0" />
      <geometry>
        <mesh
          filename="package://arm_descs/meshes/link23.STL" />
      </geometry>
    </collision>
  </link>
  <joint
    name="joint3"
    type="revolute">
    <origin
      xyz="-0.197 0 0"
      rpy="2.387E-15 -1.4789E-16 3.1396" />
    <parent
      link="link12" />
    <child
      link="link23" />
    <axis
      xyz="0 0 1" />
    <limit
      lower="-1.745329"
      upper="1.745329"
      effort="0"
      velocity="0" />
  </joint>
  <link
    name="link34">
    <inertial>
      <origin
        xyz="0.0469584100681779 -6.00648003556969E-17 -1.01915004213637E-16"
        rpy="0 0 0" />
      <mass
        value="2.79074113501019" />
      <inertia
        ixx="0.0161908942780376"
        ixy="-5.05848076100268E-18"
        ixz="5.18553570309083E-18"
        iyy="0.0114011057306674"
        iyz="4.77048955893622E-18"
        izz="0.0101991187528917" />
    </inertial>
    <visual>
      <origin
        xyz="0 0 0"
        rpy="0 0 0" />
      <geometry>
        <mesh
          filename="package://arm_descs/meshes/link34.STL" />
      </geometry>
      <material
        name="">
        <color
          rgba="0.792156862745098 0.819607843137255 0.933333333333333 1" />
      </material>
    </visual>
    <collision>
      <origin
        xyz="0 0 0"
        rpy="0 0 0" />
      <geometry>
        <mesh
          filename="package://arm_descs/meshes/link34.STL" />
      </geometry>
    </collision>
  </link>
  <joint
    name="joint4"
    type="continuous">
    <origin
      xyz="0.23939 0 0.00185"
      rpy="-3.132 1.2707E-16 9.3805E-16" />
    <parent
      link="link23" />
    <child
      link="link34" />
    <axis
      xyz="1 0 0" />
  </joint>
  <link
    name="link45">
    <inertial>
      <origin
        xyz="0.0999176864544131 -3.02709246557953E-16 6.3274038786254E-16"
        rpy="0 0 0" />
      <mass
        value="1.65897773866094" />
      <inertia
        ixx="0.00960236744018954"
        ixy="9.09713385351119E-18"
        ixz="-1.15365887416036E-18"
        iyy="0.0129478744379156"
        iyz="-2.16840434497101E-18"
        izz="0.00949418899234963" />
    </inertial>
    <visual>
      <origin
        xyz="0 0 0"
        rpy="0 0 0" />
      <geometry>
        <mesh
          filename="package://arm_descs/meshes/link45.STL" />
      </geometry>
      <material
        name="">
        <color
          rgba="0.792156862745098 0.819607843137255 0.933333333333333 1" />
      </material>
    </visual>
    <collision>
      <origin
        xyz="0 0 0"
        rpy="0 0 0" />
      <geometry>
        <mesh
          filename="package://arm_descs/meshes/link45.STL" />
      </geometry>
    </collision>
  </link>
  <joint
    name="joint5"
    type="revolute">
    <origin
      xyz="0.14561 0 0"
      rpy="8.8818E-16 2.2118E-16 0.0033306" />
    <parent
      link="link34" />
    <child
      link="link45" />
    <axis
      xyz="0 0 -1" />
    <limit
      lower="-1.745329"
      upper="1.745329"
      effort="2"
      velocity="10" />
  </joint>
  <link
    name="link56">
    <inertial>
      <origin
        xyz="-0.0806273288867452 2.77555756156289E-16 -9.10729824887824E-18"
        rpy="0 0 0" />
      <mass
        value="0.444019858497779" />
      <inertia
        ixx="0.000996979236728047"
        ixy="1.34720590260796E-18"
        ixz="-1.52465930505774E-19"
        iyy="0.00135582146654638"
        iyz="-1.62630325872826E-19"
        izz="0.00135582146654638" />
    </inertial>
    <visual>
      <origin
        xyz="0 0 0"
        rpy="0 0 0" />
      <geometry>
        <mesh
          filename="package://arm_descs/meshes/link56.STL" />
      </geometry>
      <material
        name="">
        <color
          rgba="0.792156862745098 0.819607843137255 0.933333333333333 1" />
      </material>
    </visual>
    <collision>
      <origin
        xyz="0 0 0"
        rpy="0 0 0" />
      <geometry>
        <mesh
          filename="package://arm_descs/meshes/link56.STL" />
      </geometry>
    </collision>
  </link>
  <joint
    name="joint6"
    type="prismatic">
    <origin
      xyz="0.072504 0 0"
      rpy="2.2204E-16 5.3516E-16 3.1416" />
    <parent
      link="link45" />
    <child
      link="link56" />
    <axis
      xyz="-1 0 0" />
    <limit
      lower="0"
      upper="0.1"
      effort="2"
      velocity="10" />
  </joint>
</robot>
